/home/matereza/PycharmProjects/damas-core/venv/bin/python /home/matereza/PycharmProjects/damas-core/py/async_cli/main_test.py
================================>>> test_update_many_element started
Traceback (most recent call last):
  File "/home/matereza/PycharmProjects/damas-core/py/async_cli/main_test.py", line 205, in <module>
    loop.run_until_complete(main(loop))
  File "/usr/lib/python3.9/asyncio/base_events.py", line 642, in run_until_complete
    return future.result()
  File "/home/matereza/PycharmProjects/damas-core/py/async_cli/main_test.py", line 188, in main
    await test_update_many_element(json_elts_keys_list)
  File "/home/matereza/PycharmProjects/damas-core/py/async_cli/main_test.py", line 111, in test_update_many_element
    await asyncio.gather(*tasks)
  File "/home/matereza/PycharmProjects/damas-core/py/async_cli/damas_async.py", line 216, in update
    json_result = await resp.json()
  File "/home/matereza/PycharmProjects/damas-core/venv/lib/python3.9/site-packages/aiohttp/client_reqrep.py", line 1097, in json
    raise ContentTypeError(
aiohttp.client_exceptions.ContentTypeError: 0, message='Attempt to decode JSON with unexpected mimetype: text/html; charset=utf-8', url=URL('http://localhost:8090/api/update/')

Process finished with exit code 1